Workbook

Sheet TIRATA_01_225-245
A1: PIANO DI STENDIMENTO · 132 kV QUARTAIE–MOLASSANA · TIRATA 1 · 225–245
D2: PROGETTO 23842B1 · IMPRESA ESECUTRICE ELECNOR | V2: OPGW PRYSMIAN C61 · 48 FIBRE · ETRS89 / UTM 32N
A4: DATI DELLA TIRATA | B4: Lunghezza: 3.792,16 m | N4: Bobina: 4.000,00 m | Z4: Margine: 207,84 m | AL4: Tiro: DA DEFINIRE
B5: FRENO · Tesmec PT1250 · sostegno 225 · angolo 90° · distanza 15 m · DIRETTO | X5: ARGANO · Tesmec PL1150 · sostegno 245 · angolo 0° · distanza 13 m · ROVESCIO-RINVIATO
A7: ATTRAVERSAMENTI | B7: 225–226 | D7: 226–227 | F7: 227–228 | H7: 228–229 | J7: 229–230 | L7: 230–231 | N7: 231–232 | P7: 232–233 | R7: 233–234 | T7: 234–235 | V7: 235–236 | X7: 236–237 | Z7: 237–238 | AB7: 238–239 | AD7: 239–240 | AF7: 240–241 | AH7: 241–242 | AJ7: 242–243 | AL7: 243–244 | AN7: 244–245 | AP7: FINE
A8: Tipo · riferimento | B8: =IFERROR(INDEX('04 Interferencias'!$D:$D,MATCH(SUBSTITUTE(B7,"–","-"),'04 Interferencias'!$A:$A,0)),"—") -> Torrente Lav | D8: =IFERROR(INDEX('04 Interferencias'!$D:$D,MATCH(SUBSTITUTE(D7,"–","-"),'04 Interferencias'!$A:$A,0)),"—") -> SC. BT. IP. Teleferica | F8: =IFERROR(INDEX('04 Interferencias'!$D:$D,MATCH(SUBSTITUTE(F7,"–","-"),'04 Interferencias'!$A:$A,0)),"—") -> BT in cavo casa a 5 mt. | H8: =IFERROR(INDEX('04 Interferencias'!$D:$D,MATCH(SUBSTITUTE(H7,"–","-"),'04 Interferencias'!$A:$A,0)),"—") -> casa BT in cavo A10 SC. Teleferica - capannone | J8: =IFERROR(INDEX('04 Interferencias'!$D:$D,MATCH(SUBSTITUTE(J7,"–","-"),'04 Interferencias'!$A:$A,0)),"—") -> — | L8: =IFERROR(INDEX('04 Interferencias'!$D:$D,MATCH(SUBSTITUTE(L7,"–","-"),'04 Interferencias'!$A:$A,0)),"—") -> Teleferica | N8: =IFERROR(INDEX('04 Interferencias'!$D:$D,MATCH(SUBSTITUTE(N7,"–","-"),'04 Interferencias'!$A:$A,0)),"—") -> Teleferica | P8: =IFERROR(INDEX('04 Interferencias'!$D:$D,MATCH(SUBSTITUTE(P7,"–","-"),'04 Interferencias'!$A:$A,0)),"—") -> Teleferica BT SC Str,privata | R8: =IFERROR(INDEX('04 Interferencias'!$D:$D,MATCH(SUBSTITUTE(R7,"–","-"),'04 Interferencias'!$A:$A,0)),"—") -> Vasca acqua tubo acqua | T8: =IFERROR(INDEX('04 Interferencias'!$D:$D,MATCH(SUBSTITUTE(T7,"–","-"),'04 Interferencias'!$A:$A,0)),"—") -> — | V8: =IFERROR(INDEX('04 Interferencias'!$D:$D,MATCH(SUBSTITUTE(V7,"–","-"),'04 Interferencias'!$A:$A,0)),"—") -> Vasca acquedotto BT in cavo SV. - Teleferica | X8: =IFERROR(INDEX('04 Interferencias'!$D:$D,MATCH(SUBSTITUTE(X7,"–","-"),'04 Interferencias'!$A:$A,0)),"—") -> — | Z8: =IFERROR(INDEX('04 Interferencias'!$D:$D,MATCH(SUBSTITUTE(Z7,"–","-"),'04 Interferencias'!$A:$A,0)),"—") -> Baracca | AB8: =IFERROR(INDEX('04 Interferencias'!$D:$D,MATCH(SUBSTITUTE(AB7,"–","-"),'04 Interferencias'!$A:$A,0)),"—") -> — | AD8: =IFERROR(INDEX('04 Interferencias'!$D:$D,MATCH(SUBSTITUTE(AD7,"–","-"),'04 Interferencias'!$A:$A,0)),"—") -> — | AF8: =IFERROR(INDEX('04 Interferencias'!$D:$D,MATCH(SUBSTITUTE(AF7,"–","-"),'04 Interferencias'!$A:$A,0)),"—") -> — | AH8: =IFERROR(INDEX('04 Interferencias'!$D:$D,MATCH(SUBSTITUTE(AH7,"–","-"),'04 Interferencias'!$A:$A,0)),"—") -> SP. Per Moconesi Str. Privata | AJ8: =IFERROR(INDEX('04 Interferencias'!$D:$D,MATCH(SUBSTITUTE(AJ7,"–","-"),'04 Interferencias'!$A:$A,0)),"—") -> — | AL8: =IFERROR(INDEX('04 Interferencias'!$D:$D,MATCH(SUBSTITUTE(AL7,"–","-"),'04 Interferencias'!$A:$A,0)),"—") -> SV. Baracca 2Serre torrente Neirone - BT IP SP 2BT. 2 15kV. | AN8: =IFERROR(INDEX('04 Interferencias'!$D:$D,MATCH(SUBSTITUTE(AN7,"–","-"),'04 Interferencias'!$A:$A,0)),"—") -> SV: BT in cavo | AP8: =IFERROR(INDEX('04 Interferencias'!$D:$D,MATCH(SUBSTITUTE(AP7,"–","-"),'04 Interferencias'!$A:$A,0)),"—") -> —
A10: SCHEMA DI STENDIMENTO · RAPPRESENTAZIONE SIMBOLICA NON IN SCALA
A28: N° SOSTEGNO | B28: 225 | D28: 226 | F28: 227 | H28: 228 | J28: 229 | L28: 230 | N28: 231 | P28: 232 | R28: 233 | T28: 234 | V28: 235 | X28: 236 | Z28: 237 | AB28: 238 | AD28: 239 | AF28: 240 | AH28: 241 | AJ28: 242 | AL28: 243 | AN28: 244 | AP28: 245
A29: TIPO | B29: AMARRO | D29: AMARRO | F29: AMARRO | H29: SOSPENSIONE | J29: AMARRO | L29: AMARRO | N29: SOSPENSIONE | P29: AMARRO | R29: SOSPENSIONE | T29: SOSPENSIONE | V29: AMARRO | X29: SOSPENSIONE | Z29: AMARRO | AB29: SOSPENSIONE | AD29: SOSPENSIONE | AF29: AMARRO | AH29: AMARRO | AJ29: AMARRO | AL29: AMARRO | AN29: AMARRO | AP29: SOSPENSIONE
A30: ALTEZZA [m] | B30: 23.8 | D30: 22.6 | F30: 22.6 | H30: 29.8 | J30: 25.3 | L30: 25.8 | N30: 25.6 | P30: 22.6 | R30: 22.5 | T30: 25 | V30: 25.7 | X30: 22.6 | Z30: 22.1 | AB30: 22.4 | AD30: 20.3 | AF30: 20.9 | AH30: 22.1 | AJ30: 25.4 | AL30: 22.4 | AN30: 22.1
A31: QUOTA [m s.l.m.] | B31: 130.55 | D31: 141.55 | F31: 182.63 | H31: 204.04 | J31: 179.03 | L31: 222.42 | N31: 230.44 | P31: 220.24 | R31: 201.37 | T31: 213.04 | V31: 227.45 | X31: 260.79 | Z31: 237.85 | AB31: 264.61 | AD31: 249.92 | AF31: 233.38 | AH31: 220.72 | AJ31: 258.2 | AL31: 215.9 | AN31: 253.7 | AP31: 245.73
A32: ANGOLO LINEA [°] | D32: 179.99 | F32: 180 | H32: 179.89 | J32: 179.99 | L32: 179.9 | N32: 179.92 | P32: 167.16 | R32: 179.91 | T32: 179.8 | V32: 179.79 | X32: 179.87 | Z32: 179.77 | AB32: 179.92 | AD32: 179.87 | AF32: 179.78 | AH32: 179.84 | AJ32: 177.47 | AL32: 179.93 | AN32: 177.36 | AP32: 179.91
A33: UTM EST [m] | B33: 517441.26 | D33: 517290.8 | F33: 517148.14 | H33: 517078.75 | J33: 516957.49 | L33: 516766.68 | N33: 516609.26 | P33: 516497.18 | R33: 516360.48 | T33: 516116.8 | V33: 516032.64 | X33: 515783.9 | Z33: 515557.44 | AB33: 515418.73 | AD33: 515290.95 | AF33: 515166.91 | AH33: 515063 | AJ33: 514851.42 | AL33: 514758.46 | AN33: 514422.99 | AP33: 514370.71
A34: UTM NORD [m] | B34: 4918351.8 | D34: 4918465.5 | F34: 4918573.3 | H34: 4918625.7 | J34: 4918717.7 | L34: 4918862.3 | N34: 4918981.2 | P34: 4919066.1 | R34: 4919127.8 | T34: 4919238.2 | V34: 4919276 | X34: 4919388.8 | Z34: 4919490.9 | AB34: 4919554.1 | AD34: 4919612.1 | AF34: 4919668 | AH34: 4919715.4 | AJ34: 4919811.1 | AL34: 4919848.3 | AN34: 4919983.1 | AP34: 4920001.3
A35: CAMPATA [m] | C35: 188.58 | E35: 178.79 | G35: 86.96 | I35: 152.19 | K35: 239.44 | M35: 197.27 | O35: 140.59 | Q35: 149.98 | S35: 267.54 | U35: 92.26 | W35: 273.11 | Y35: 248.4 | AA35: 152.43 | AC35: 140.33 | AE35: 136.08 | AG35: 114.19 | AI35: 232.23 | AK35: 100.13 | AM35: 361.53 | AO35: 55.37
A36: TIRO PER VANO [daN] a 10ºC | C36: =TESATURA_NORMALIZADA!G6 -> 344 | E36: =TESATURA_NORMALIZADA!G7 -> 388 | G36: =TESATURA_NORMALIZADA!G8 -> 1532 | I36: =TESATURA_NORMALIZADA!G9 -> 427 | K36: =TESATURA_NORMALIZADA!G10 -> 332 | M36: =TESATURA_NORMALIZADA!G11 -> 373 | O36: =TESATURA_NORMALIZADA!G12 -> 653 | Q36: =TESATURA_NORMALIZADA!G13 -> 297 | S36: =TESATURA_NORMALIZADA!G14 -> 351 | U36: =TESATURA_NORMALIZADA!G15 -> 816 | W36: =TESATURA_NORMALIZADA!G16 -> 350 | Y36: =TESATURA_NORMALIZADA!G17 -> 346 | AA36: =TESATURA_NORMALIZADA!G18 -> 509 | AC36: =TESATURA_NORMALIZADA!G19 -> 369 | AE36: =TESATURA_NORMALIZADA!G20 -> 386 | AG36: =TESATURA_NORMALIZADA!G21 -> 494 | AI36: =TESATURA_NORMALIZADA!G22 -> 366 | AK36: =TESATURA_NORMALIZADA!G23 -> 556 | AM36: =TESATURA_NORMALIZADA!G24 -> 346 | AO36: =TESATURA_NORMALIZADA!G25 -> 1346
A37: PROGRESSIVA [m] | B37: 0,00 | D37: 188,58 | F37: 367,36 | H37: 454,32 | J37: 606,51 | L37: 845,95 | N37: 1.043,23 | P37: 1.183,82 | R37: 1.333,80 | T37: 1.601,34 | V37: 1.693,60 | X37: 1.966,71 | Z37: 2.215,11 | AB37: 2.367,54 | AD37: 2.507,87 | AF37: 2.643,95 | AH37: 2.758,15 | AJ37: 2.990,38 | AL37: 3.090,51 | AN37: 3.452,03 | AP37: 3.507,41
A38: TIRATA [m] | B38: =SUM(C35:AP35) -> 3507.4
A39: CONDUTTORE E OPGW · PIANO BOBINE
A40: TIPO DI CONDUTTORE
A41: PIANO BOBINA CONDUTTORE
A42: TIPO DI OPGW / FIBRA OTTICA | B42: OPGW Prysmian C61 · 48 fibre ottiche · caratteristiche definitive secondo scheda tecnica approvata
A43: PIANO BOBINA OPGW | B43: Bobina nominale 4.000,00 m · lunghezza tirata 3.792,16 m · margine operativo 207,84 m
A44: NOTE DAL PIANO BOBINE | B44: DA DEFINIRE
A46: FERRAMENTA · MONTAGGIO (NUOVO DA INSTALLARE)
A47: CATENA DI AMARRO (DA) | B47: LM252: morsetto 603 + 2×522/2 + 2×401/1 (rif. C23, C51) | D47: LM252: morsetto 603 + 2×522/2 + 2×401/1 (rif. C23, C51) | F47: LM252: morsetto 603 + 2×522/2 + 2×401/1 (rif. C23, C51) | H47: LM252: morsetto 603 + 2×522/2 + 2×401/1 (rif. C23, C51) | J47: LM252: morsetto 603 + 2×522/2 + 2×401/1 (rif. C23, C51) | L47: LM252: morsetto 603 + 2×522/2 + 2×401/1 (rif. C23, C51) | N47: LM252: morsetto 603 + 2×522/2 + 2×401/1 (rif. C23, C51) | P47: LM252: morsetto 603 + 2×522/2 + 2×401/1 (rif. C23, C51) | R47: LM252: morsetto 603 + 2×522/2 + 2×401/1 (rif. C23, C51) | T47: LM252: morsetto 603 + 2×522/2 + 2×401/1 (rif. C23, C51) | V47: LM252: morsetto 603 + 2×522/2 + 2×401/1 (rif. C23, C51) | X47: LM252: morsetto 603 + 2×522/2 + 2×401/1 (rif. C23, C51) | Z47: LM252: morsetto 603 + 2×522/2 + 2×401/1 (rif. C23, C51) | AB47: LM252: morsetto 603 + 2×522/2 + 2×401/1 (rif. C23, C51) | AD47: LM252: morsetto 603 + 2×522/2 + 2×401/1 (rif. C23, C51) | AF47: LM252: morsetto 603 + 2×522/2 + 2×401/1 (rif. C23, C51) | AH47: LM252: morsetto 603 + 2×522/2 + 2×401/1 (rif. C23, C51) | AJ47: LM252: morsetto 603 + 2×522/2 + 2×401/1 (rif. C23, C51) | AL47: LM252: morsetto 603 + 2×522/2 + 2×401/1 (rif. C23, C51) | AN47: LM252: morsetto 603 + 2×522/2 + 2×401/1 (rif. C23, C51) | AP47: LM252: morsetto 603 + 2×522/2 + 2×401/1 (rif. C23, C51)
A48: CATENA DI SOSPENSIONE (V)
A49: CATENA D'ANGOLO (TA2)
A50: CATENA AUSILIARIA
A51: NOTE
A52: FERRAMENTA · SMONTAGGIO (ESISTENTE DA SMONTARE)
A53: CATENA DI AMARRO (DA) | B53: LM252: morsetto 603 + 2×522/2 + 2×401/1 (rif. C23, C51) | D53: LM252: morsetto 603 + 2×522/2 + 2×401/1 (rif. C23, C51) | F53: LM252: morsetto 603 + 2×522/2 + 2×401/1 (rif. C23, C51) | H53: LM252: morsetto 603 + 2×522/2 + 2×401/1 (rif. C23, C51) | J53: LM252: morsetto 603 + 2×522/2 + 2×401/1 (rif. C23, C51) | L53: LM252: morsetto 603 + 2×522/2 + 2×401/1 (rif. C23, C51) | N53: LM252: morsetto 603 + 2×522/2 + 2×401/1 (rif. C23, C51) | P53: LM252: morsetto 603 + 2×522/2 + 2×401/1 (rif. C23, C51) | R53: LM252: morsetto 603 + 2×522/2 + 2×401/1 (rif. C23, C51) | T53: LM252: morsetto 603 + 2×522/2 + 2×401/1 (rif. C23, C51) | V53: LM252: morsetto 603 + 2×522/2 + 2×401/1 (rif. C23, C51) | X53: LM252: morsetto 603 + 2×522/2 + 2×401/1 (rif. C23, C51) | Z53: LM252: morsetto 603 + 2×522/2 + 2×401/1 (rif. C23, C51) | AB53: LM252: morsetto 603 + 2×522/2 + 2×401/1 (rif. C23, C51) | AD53: LM252: morsetto 603 + 2×522/2 + 2×401/1 (rif. C23, C51) | AF53: LM252: morsetto 603 + 2×522/2 + 2×401/1 (rif. C23, C51) | AH53: LM252: morsetto 603 + 2×522/2 + 2×401/1 (rif. C23, C51) | AJ53: LM252: morsetto 603 + 2×522/2 + 2×401/1 (rif. C23, C51) | AL53: LM252: morsetto 603 + 2×522/2 + 2×401/1 (rif. C23, C51) | AN53: LM252: morsetto 603 + 2×522/2 + 2×401/1 (rif. C23, C51) | AP53: LM252: morsetto 603 + 2×522/2 + 2×401/1 (rif. C23, C51)
A54: CATENA DI SOSPENSIONE (V)
A55: CATENA D'ANGOLO (TA2)
A56: CATENA AUSILIARIA
A57: NOTE
A58: Documento di lavoro ELECNOR · Progetto 23842B1 · Linea Quartaie–Molassana · Dati geometrici da DXF / tabella di picchettamento

Sheet TIRATA_02_245-267
A1: PIANO DI STENDIMENTO · 132 kV QUARTAIE–MOLASSANA · TIRATA 2 · 245–267
E2: PROGETTO 23842B1 · IMPRESA ESECUTRICE ELECNOR | Y2: OPGW PRYSMIAN C61 · 48 FIBRE · ETRS89 / UTM 32N
A4: DATI DELLA TIRATA | C4: Lunghezza: 4.524,80 m | O4: Bobina: 5.000,00 m | AA4: Margine: 475,20 m | AM4: Tiro: DA DEFINIRE
A5: FRENO · Tesmec PT1250 · sostegno 245 · angolo 0° · distanza 13 m · DIRETTO | AA5: ARGANO · Tesmec PL1150 · sostegno 267 · angolo 25° · distanza 20 m · DIRETTO
A7: ATTRAVERSAMENTI | B7: 245–246 | D7: 246–247 | F7: 247–248 | H7: 248–249 | J7: 249–250 | L7: 250–251 | N7: 251–252 | P7: 252–253 | R7: 253–254 | T7: 254–255 | V7: 255–256 | X7: 256–257 | Z7: 257–258 | AB7: 258–259 | AD7: 259–260 | AF7: 260–261 | AH7: 261–262 | AJ7: 262–263 | AL7: 263–264 | AN7: 264–265 | AP7: 265–266 | AR7: 266–267 | AT7: FINE
A8: Tipo · riferimento | B8: =IFERROR(INDEX('04 Interferencias'!$D:$D,MATCH(SUBSTITUTE(B7,"–","-"),'04 Interferencias'!$A:$A,0)),"—") -> Capannone SV. BT in cavo - 2 15kV. | D8: =IFERROR(INDEX('04 Interferencias'!$D:$D,MATCH(SUBSTITUTE(D7,"–","-"),'04 Interferencias'!$A:$A,0)),"—") -> BT in cavo BT privata SC. BT - Str, privata | F8: =IFERROR(INDEX('04 Interferencias'!$D:$D,MATCH(SUBSTITUTE(F7,"–","-"),'04 Interferencias'!$A:$A,0)),"—") -> — | H8: =IFERROR(INDEX('04 Interferencias'!$D:$D,MATCH(SUBSTITUTE(H7,"–","-"),'04 Interferencias'!$A:$A,0)),"—") -> — | J8: =IFERROR(INDEX('04 Interferencias'!$D:$D,MATCH(SUBSTITUTE(J7,"–","-"),'04 Interferencias'!$A:$A,0)),"—") -> — | L8: =IFERROR(INDEX('04 Interferencias'!$D:$D,MATCH(SUBSTITUTE(L7,"–","-"),'04 Interferencias'!$A:$A,0)),"—") -> — | N8: =IFERROR(INDEX('04 Interferencias'!$D:$D,MATCH(SUBSTITUTE(N7,"–","-"),'04 Interferencias'!$A:$A,0)),"—") -> Baracca SV. BT in cavo | P8: =IFERROR(INDEX('04 Interferencias'!$D:$D,MATCH(SUBSTITUTE(P7,"–","-"),'04 Interferencias'!$A:$A,0)),"—") -> Torrente Lav. SS. 225 - 66kV FS | R8: =IFERROR(INDEX('04 Interferencias'!$D:$D,MATCH(SUBSTITUTE(R7,"–","-"),'04 Interferencias'!$A:$A,0)),"—") -> — | T8: =IFERROR(INDEX('04 Interferencias'!$D:$D,MATCH(SUBSTITUTE(T7,"–","-"),'04 Interferencias'!$A:$A,0)),"—") -> — | V8: =IFERROR(INDEX('04 Interferencias'!$D:$D,MATCH(SUBSTITUTE(V7,"–","-"),'04 Interferencias'!$A:$A,0)),"—") -> Teleferica | X8: =IFERROR(INDEX('04 Interferencias'!$D:$D,MATCH(SUBSTITUTE(X7,"–","-"),'04 Interferencias'!$A:$A,0)),"—") -> Rustico | Z8: =IFERROR(INDEX('04 Interferencias'!$D:$D,MATCH(SUBSTITUTE(Z7,"–","-"),'04 Interferencias'!$A:$A,0)),"—") -> SP. Per Lumarzo L. telefono | AB8: =IFERROR(INDEX('04 Interferencias'!$D:$D,MATCH(SUBSTITUTE(AB7,"–","-"),'04 Interferencias'!$A:$A,0)),"—") -> — | AD8: =IFERROR(INDEX('04 Interferencias'!$D:$D,MATCH(SUBSTITUTE(AD7,"–","-"),'04 Interferencias'!$A:$A,0)),"—") -> 15kV. SC. Str. Privata | AF8: =IFERROR(INDEX('04 Interferencias'!$D:$D,MATCH(SUBSTITUTE(AF7,"–","-"),'04 Interferencias'!$A:$A,0)),"—") -> — | AH8: =IFERROR(INDEX('04 Interferencias'!$D:$D,MATCH(SUBSTITUTE(AH7,"–","-"),'04 Interferencias'!$A:$A,0)),"—") -> — | AJ8: =IFERROR(INDEX('04 Interferencias'!$D:$D,MATCH(SUBSTITUTE(AJ7,"–","-"),'04 Interferencias'!$A:$A,0)),"—") -> — | AL8: =IFERROR(INDEX('04 Interferencias'!$D:$D,MATCH(SUBSTITUTE(AL7,"–","-"),'04 Interferencias'!$A:$A,0)),"—") -> — | AN8: =IFERROR(INDEX('04 Interferencias'!$D:$D,MATCH(SUBSTITUTE(AN7,"–","-"),'04 Interferencias'!$A:$A,0)),"—") -> — | AP8: =IFERROR(INDEX('04 Interferencias'!$D:$D,MATCH(SUBSTITUTE(AP7,"–","-"),'04 Interferencias'!$A:$A,0)),"—") -> — | AR8: =IFERROR(INDEX('04 Interferencias'!$D:$D,MATCH(SUBSTITUTE(AR7,"–","-"),'04 Interferencias'!$A:$A,0)),"—") -> 4 telefoniche SS. Cascinale - baracca lamiera | AT8: =IFERROR(INDEX('04 Interferencias'!$D:$D,MATCH(SUBSTITUTE(AT7,"–","-"),'04 Interferencias'!$A:$A,0)),"—") -> —
A10: SCHEMA DI STENDIMENTO · RAPPRESENTAZIONE SIMBOLICA NON IN SCALA
A28: N° SOSTEGNO | B28: 245 | D28: 246 | F28: 247 | H28: 248 | J28: 249 | L28: 250 | N28: 251 | P28: 252 | R28: 253 | T28: 254 | V28: 255 | X28: 256 | Z28: 257 | AB28: 258 | AD28: 259 | AF28: 260 | AH28: 261 | AJ28: 262 | AL28: 263 | AN28: 264 | AP28: 265 | AR28: 266 | AT28: 267
A29: TIPO | B29: SOSPENSIONE | D29: AMARRO | F29: SOSPENSIONE | H29: SOSPENSIONE | J29: SOSPENSIONE | L29: SOSPENSIONE | N29: AMARRO | P29: AMARRO | R29: AMARRO | T29: SOSPENSIONE | V29: AMARRO | X29: AMARRO | Z29: AMARRO | AB29: SOSPENSIONE | AD29: AMARRO | AF29: SOSPENSIONE | AH29: SOSPENSIONE | AJ29: SOSPENSIONE | AL29: SOSPENSIONE | AN29: AMARRO | AP29: SOSPENSIONE | AR29: AMARRO | AT29: AMARRO
A30: ALTEZZA [m] | B30: 22.6 | D30: 25.4 | F30: 22.4 | H30: 22.4 | J30: 22.3 | L30: 22.4 | N30: 22.3 | P30: 28.7 | R30: 21.8 | T30: 22.8 | V30: 26.3 | X30: 23.5 | Z30: 28 | AB30: 23.3 | AD30: 22.2 | AF30: 30.4 | AH30: 22.3 | AJ30: 22.3 | AL30: 29.8 | AN30: 22.6 | AP30: 23.1 | AR30: 35.5 | AT30: 35.5
A31: QUOTA [m s.l.m.] | B31: 245.73 | D31: 190.39 | F31: 220.38 | H31: 216.82 | J31: 243.96 | L31: 258.9 | N31: 248.86 | P31: 235.02 | R31: 206.6 | T31: 228.91 | V31: 235.83 | X31: 282.42 | Z31: 280.12 | AB31: 332.68 | AD31: 329.73 | AF31: 433 | AH31: 452.94 | AJ31: 442.49 | AL31: 386.73 | AN31: 353.9 | AP31: 311.69 | AR31: 307.92 | AT31: 343.34
A32: ANGOLO LINEA [°] | D32: 179.92 | F32: 179.65 | H32: 179.95 | J32: 179.2 | L32: 179.69 | N32: 156.82 | P32: 179.95 | R32: 160.7 | T32: 179.67 | V32: 179.75 | X32: 128.38 | Z32: 155.56 | AB32: 179.85 | AD32: 179.89 | AF32: 179.96 | AH32: 179.99 | AJ32: 179.99 | AL32: 179.98 | AN32: 179.96 | AP32: 177.18 | AR32: 141.39 | AT32: 135.01
A33: UTM EST [m] | B33: 514370.71 | D33: 514166.11 | F33: 513938.72 | H33: 513711.09 | J33: 513552.34 | L33: 513440.28 | N33: 513243.69 | P33: 513051.37 | R33: 512768.56 | T33: 512696.33 | V33: 512554.45 | X33: 512355.73 | Z33: 512047.17 | AB33: 511900.01 | AD33: 511672.41 | AF33: 511464.76 | AH33: 511162.49 | AJ33: 511059.5 | AL33: 510843.92 | AN33: 510643.51 | AP33: 510453.07 | AR33: 510196.51 | AT33: 510075.86
A34: UTM NORD [m] | B34: 4920001.3 | D34: 4920072.4 | F34: 4920151.7 | H34: 4920229.6 | J34: 4920284 | L34: 4920324.2 | N34: 4920393.5 | P34: 4920380.8 | R34: 4920362.5 | T34: 4920331.8 | V34: 4920270.6 | X34: 4920183.9 | Z34: 4920348.2 | AB34: 4920357.5 | AD34: 4920371.2 | AF34: 4920383.3 | AH34: 4920401.2 | AJ34: 4920407.3 | AL34: 4920420 | AN34: 4920431.8 | AP34: 4920443.2 | AR34: 4920445.7 | AT34: 4920544.1
A35: CAMPATA [m] | C35: 216.59 | E35: 240.82 | G35: 240.57 | I35: 167.82 | K35: 119.05 | M35: 208.45 | O35: 192.74 | Q35: 283.4 | S35: 78.47 | U35: 154.52 | W35: 216.83 | Y35: 349.6 | AA35: 147.45 | AC35: 228.01 | AE35: 208 | AG35: 302.8 | AI35: 103.17 | AK35: 215.96 | AM35: 200.76 | AO35: 190.78 | AQ35: 256.57 | AS35: 155.67
A36: TIRO PER VANO [daN] | C36: =TESATURA_NORMALIZADA!G26 -> 351 | E36: =TESATURA_NORMALIZADA!G27 -> 381 | G36: =TESATURA_NORMALIZADA!G28 -> 375 | I36: =TESATURA_NORMALIZADA!G29 -> 329 | K36: =TESATURA_NORMALIZADA!G30 -> 1477 | M36: =TESATURA_NORMALIZADA!G31 -> 406 | O36: =TESATURA_NORMALIZADA!G32 -> 404 | Q36: =TESATURA_NORMALIZADA!G33 -> 382 | S36: =TESATURA_NORMALIZADA!G34 -> 638 | U36: =TESATURA_NORMALIZADA!G35 -> 392 | W36: =TESATURA_NORMALIZADA!G36 -> 407 | Y36: =TESATURA_NORMALIZADA!G37 -> 378 | AA36: =TESATURA_NORMALIZADA!G38 -> 439 | AC36: =TESATURA_NORMALIZADA!G39 -> 359 | AE36: =TESATURA_NORMALIZADA!G40 -> 524 | AG36: =TESATURA_NORMALIZADA!G41 -> 378 | AI36: =TESATURA_NORMALIZADA!G42 -> 601 | AK36: =TESATURA_NORMALIZADA!G43 -> 395 | AM36: =TESATURA_NORMALIZADA!G44 -> 406 | AO36: =TESATURA_NORMALIZADA!G45 -> 358 | AQ36: =TESATURA_NORMALIZADA!G46 -> 471 | AS36: =TESATURA_NORMALIZADA!G47 -> 401
A37: PROGRESSIVA [m] | B37: 0 | D37: 216.59 | F37: 457.41 | H37: 697.98 | J37: 865.81 | L37: 984.85 | N37: 1193.3 | P37: 1386.04 | R37: 1669.44 | T37: 1747.91 | V37: 1902.43 | X37: 2119.26 | Z37: 2468.86 | AB37: 2616.31 | AD37: 2844.32 | AF37: 3052.33 | AH37: 3355.13 | AJ37: 3458.29 | AL37: 3674.25 | AN37: 3875.01 | AP37: 4065.78 | AR37: 4322.36 | AT37: 4478.03
A38: TIRATA [m] | B38: =SUM(C35:AS35) -> 4478.03
A39: CONDUTTORE E OPGW · PIANO BOBINE
A40: TIPO DI CONDUTTORE | B40: DA DEFINIRE
A41: PIANO BOBINA CONDUTTORE | B41: DA DEFINIRE
A42: TIPO DI OPGW / FIBRA OTTICA | B42: OPGW Prysmian C61 · 48 fibre ottiche · caratteristiche definitive secondo scheda tecnica approvata
A43: PIANO BOBINA OPGW | B43: Bobina nominale 5.000,00 m · lunghezza tirata 4.524,80 m · margine operativo 475,20 m
A44: NOTE DAL PIANO BOBINE | B44: DA DEFINIRE
A46: FERRAMENTA · MONTAGGIO (NUOVO DA INSTALLARE)
A47: CATENA DI AMARRO (DA) | B47: LM252: morsetto 603 + 2×522/2 + 2×401/1 (rif. C23, C51) | D47: LM252: morsetto 603 + 2×522/2 + 2×401/1 (rif. C23, C51) | F47: LM252: morsetto 603 + 2×522/2 + 2×401/1 (rif. C23, C51) | H47: LM252: morsetto 603 + 2×522/2 + 2×401/1 (rif. C23, C51) | J47: LM252: morsetto 603 + 2×522/2 + 2×401/1 (rif. C23, C51) | L47: LM252: morsetto 603 + 2×522/2 + 2×401/1 (rif. C23, C51) | N47: LM252: morsetto 603 + 2×522/2 + 2×401/1 (rif. C23, C51) | P47: LM252: morsetto 603 + 2×522/2 + 2×401/1 (rif. C23, C51) | R47: LM252: morsetto 603 + 2×522/2 + 2×401/1 (rif. C23, C51) | T47: LM252: morsetto 603 + 2×522/2 + 2×401/1 (rif. C23, C51) | V47: LM252: morsetto 603 + 2×522/2 + 2×401/1 (rif. C23, C51) | X47: LM252: morsetto 603 + 2×522/2 + 2×401/1 (rif. C23, C51) | Z47: LM252: morsetto 603 + 2×522/2 + 2×401/1 (rif. C23, C51) | AB47: LM252: morsetto 603 + 2×522/2 + 2×401/1 (rif. C23, C51) | AD47: LM252: morsetto 603 + 2×522/2 + 2×401/1 (rif. C23, C51) | AF47: LM252: morsetto 603 + 2×522/2 + 2×401/1 (rif. C23, C51) | AH47: LM252: morsetto 603 + 2×522/2 + 2×401/1 (rif. C23, C51) | AJ47: LM252: morsetto 603 + 2×522/2 + 2×401/1 (rif. C23, C51) | AL47: LM252: morsetto 603 + 2×522/2 + 2×401/1 (rif. C23, C51) | AN47: LM252: morsetto 603 + 2×522/2 + 2×401/1 (rif. C23, C51) | AP47: LM252: morsetto 603 + 2×522/2 + 2×401/1 (rif. C23, C51) | AR47: LM252: morsetto 603 + 2×522/2 + 2×401/1 (rif. C23, C51) | AT47: LM252: morsetto 603 + 2×522/2 + 2×401/1 (rif. C23, C51)
A48: CATENA DI SOSPENSIONE (V)
A49: CATENA D'ANGOLO (TA2)
A50: CATENA AUSILIARIA
A51: NOTE
A52: FERRAMENTA · SMONTAGGIO (ESISTENTE DA SMONTARE)
A53: CATENA DI AMARRO (DA) | B53: LM252: morsetto 603 + 2×522/2 + 2×401/1 (rif. C23, C51) | D53: LM252: morsetto 603 + 2×522/2 + 2×401/1 (rif. C23, C51) | F53: LM252: morsetto 603 + 2×522/2 + 2×401/1 (rif. C23, C51) | H53: LM252: morsetto 603 + 2×522/2 + 2×401/1 (rif. C23, C51) | J53: LM252: morsetto 603 + 2×522/2 + 2×401/1 (rif. C23, C51) | L53: LM252: morsetto 603 + 2×522/2 + 2×401/1 (rif. C23, C51) | N53: LM252: morsetto 603 + 2×522/2 + 2×401/1 (rif. C23, C51) | P53: LM252: morsetto 603 + 2×522/2 + 2×401/1 (rif. C23, C51) | R53: LM252: morsetto 603 + 2×522/2 + 2×401/1 (rif. C23, C51) | T53: LM252: morsetto 603 + 2×522/2 + 2×401/1 (rif. C23, C51) | V53: LM252: morsetto 603 + 2×522/2 + 2×401/1 (rif. C23, C51) | X53: LM252: morsetto 603 + 2×522/2 + 2×401/1 (rif. C23, C51) | Z53: LM252: morsetto 603 + 2×522/2 + 2×401/1 (rif. C23, C51) | AB53: LM252: morsetto 603 + 2×522/2 + 2×401/1 (rif. C23, C51) | AD53: LM252: morsetto 603 + 2×522/2 + 2×401/1 (rif. C23, C51) | AF53: LM252: morsetto 603 + 2×522/2 + 2×401/1 (rif. C23, C51) | AH53: LM252: morsetto 603 + 2×522/2 + 2×401/1 (rif. C23, C51) | AJ53: LM252: morsetto 603 + 2×522/2 + 2×401/1 (rif. C23, C51) | AL53: LM252: morsetto 603 + 2×522/2 + 2×401/1 (rif. C23, C51) | AN53: LM252: morsetto 603 + 2×522/2 + 2×401/1 (rif. C23, C51) | AP53: LM252: morsetto 603 + 2×522/2 + 2×401/1 (rif. C23, C51) | AR53: LM252: morsetto 603 + 2×522/2 + 2×401/1 (rif. C23, C51) | AT53: LM252: morsetto 603 + 2×522/2 + 2×401/1 (rif. C23, C51)
A54: CATENA DI SOSPENSIONE (V)
A55: CATENA D'ANGOLO (TA2)
A56: CATENA AUSILIARIA
A57: NOTE

Sheet TIRATA_03_267-285
A1: PIANO DI STENDIMENTO · 132 kV QUARTAIE–MOLASSANA · TIRATA 3 · 267–285
D2: PROGETTO 23842B1 · IMPRESA ESECUTRICE ELECNOR | T2: OPGW PRYSMIAN C61 · 48 FIBRE · ETRS89 / UTM 32N
A4: DATI DELLA TIRATA | B4: Lunghezza: 3.304,34 m | L4: Bobina: 3.500,00 m | V4: Margine: 195,66 m | AF4: Tiro: DA DEFINIRE
A5: FRENO · Tesmec PT1250 · sostegno 267 · angolo 90° · distanza 11 m · DIRETTO | V5: ARGANO · Tesmec PL1150 · sostegno 285 · angolo 35° · distanza 37 m · ROVESCIO-RINVIATO
A7: ATTRAVERSAMENTI | B7: 267–268 | D7: 268–269 | F7: 269–270 | H7: 270–271 | J7: 271–272 | L7: 272–273 | N7: 273–274 | P7: 274–275 | R7: 275–276 | T7: 276–277 | V7: 277–278 | X7: 278–279 | Z7: 279–280 | AB7: 280–281 | AD7: 281–282 | AF7: 282–283 | AH7: 283–284 | AJ7: 284–285 | AL7: FINE
A8: Tipo · riferimento | B8: =IFERROR(INDEX('04 Interferencias'!$D:$D,MATCH(SUBSTITUTE(B7,"–","-"),'04 Interferencias'!$A:$A,0)),"—") -> BT in cavo BT IP.2SC Str. Privata | D8: =IFERROR(INDEX('04 Interferencias'!$D:$D,MATCH(SUBSTITUTE(D7,"–","-"),'04 Interferencias'!$A:$A,0)),"—") -> — | F8: =IFERROR(INDEX('04 Interferencias'!$D:$D,MATCH(SUBSTITUTE(F7,"–","-"),'04 Interferencias'!$A:$A,0)),"—") -> — | H8: =IFERROR(INDEX('04 Interferencias'!$D:$D,MATCH(SUBSTITUTE(H7,"–","-"),'04 Interferencias'!$A:$A,0)),"—") -> — | J8: =IFERROR(INDEX('04 Interferencias'!$D:$D,MATCH(SUBSTITUTE(J7,"–","-"),'04 Interferencias'!$A:$A,0)),"—") -> SC. | L8: =IFERROR(INDEX('04 Interferencias'!$D:$D,MATCH(SUBSTITUTE(L7,"–","-"),'04 Interferencias'!$A:$A,0)),"—") -> — | N8: =IFERROR(INDEX('04 Interferencias'!$D:$D,MATCH(SUBSTITUTE(N7,"–","-"),'04 Interferencias'!$A:$A,0)),"—") -> — | P8: =IFERROR(INDEX('04 Interferencias'!$D:$D,MATCH(SUBSTITUTE(P7,"–","-"),'04 Interferencias'!$A:$A,0)),"—") -> — | R8: =IFERROR(INDEX('04 Interferencias'!$D:$D,MATCH(SUBSTITUTE(R7,"–","-"),'04 Interferencias'!$A:$A,0)),"—") -> 2BT in cavo 2BT. IP. SC. Baracca | T8: =IFERROR(INDEX('04 Interferencias'!$D:$D,MATCH(SUBSTITUTE(T7,"–","-"),'04 Interferencias'!$A:$A,0)),"—") -> BT. IP. SP. Per S. Alberto | V8: =IFERROR(INDEX('04 Interferencias'!$D:$D,MATCH(SUBSTITUTE(V7,"–","-"),'04 Interferencias'!$A:$A,0)),"—") -> 15 kV. | X8: =IFERROR(INDEX('04 Interferencias'!$D:$D,MATCH(SUBSTITUTE(X7,"–","-"),'04 Interferencias'!$A:$A,0)),"—") -> — | Z8: =IFERROR(INDEX('04 Interferencias'!$D:$D,MATCH(SUBSTITUTE(Z7,"–","-"),'04 Interferencias'!$A:$A,0)),"—") -> — | AB8: =IFERROR(INDEX('04 Interferencias'!$D:$D,MATCH(SUBSTITUTE(AB7,"–","-"),'04 Interferencias'!$A:$A,0)),"—") -> — | AD8: =IFERROR(INDEX('04 Interferencias'!$D:$D,MATCH(SUBSTITUTE(AD7,"–","-"),'04 Interferencias'!$A:$A,0)),"—") -> 15 kV precordato | AF8: =IFERROR(INDEX('04 Interferencias'!$D:$D,MATCH(SUBSTITUTE(AF7,"–","-"),'04 Interferencias'!$A:$A,0)),"—") -> BT. | AH8: =IFERROR(INDEX('04 Interferencias'!$D:$D,MATCH(SUBSTITUTE(AH7,"–","-"),'04 Interferencias'!$A:$A,0)),"—") -> BT. | AJ8: =IFERROR(INDEX('04 Interferencias'!$D:$D,MATCH(SUBSTITUTE(AJ7,"–","-"),'04 Interferencias'!$A:$A,0)),"—") -> SS. N° 45 | AL8: =IFERROR(INDEX('04 Interferencias'!$D:$D,MATCH(SUBSTITUTE(AL7,"–","-"),'04 Interferencias'!$A:$A,0)),"—") -> —
A10: SCHEMA DI STENDIMENTO · RAPPRESENTAZIONE SIMBOLICA NON IN SCALA
A28: N° SOSTEGNO | B28: 267 | D28: 268 | F28: 269 | H28: 270 | J28: 271 | L28: 272 | N28: 273 | P28: 274 | R28: 275 | T28: 276 | V28: 277 | X28: 278 | Z28: 279 | AB28: 280 | AD28: 281 | AF28: 282 | AH28: 283 | AJ28: 284 | AL28: 285
A29: TIPO | B29: AMARRO | D29: AMARRO | F29: AMARRO | H29: SOSPENSIONE | J29: AMARRO | L29: AMARRO | N29: AMARRO | P29: AMARRO | R29: AMARRO | T29: SOSPENSIONE | V29: AMARRO | X29: SOSPENSIONE | Z29: AMARRO | AB29: SOSPENSIONE | AD29: SOSPENSIONE | AF29: SOSPENSIONE | AH29: AMARRO | AJ29: AMARRO | AL29: AMARRO
A30: ALTEZZA [m] | B30: 35.5 | D30: 30.9 | F30: 22.6 | H30: 25.4 | J30: 25.2 | L30: 26.2 | N30: 23.9 | P30: 29.5 | R30: 23.1 | T30: 22.5 | V30: 23.4 | X30: 24.8 | Z30: 24.8 | AB30: 22.4 | AD30: 22.5 | AF30: 22.4 | AH30: 29.6 | AJ30: 25.9 | AL30: 23.5
A31: QUOTA [m s.l.m.] | B31: 343.34 | D31: 368.32 | F31: 347.3 | H31: 416.97 | J31: 494.2 | L31: 539.75 | N31: 569.01 | P31: 668.83 | R31: 720.95 | T31: 682.51 | V31: 626.73 | X31: 604.9 | Z31: 599.52 | AB31: 514.28 | AD31: 480.1 | AF31: 450.78 | AH31: 420.4 | AJ31: 378.7 | AL31: 344.01
A32: ANGOLO LINEA [°] | B32: 135.01 | D32: 172.18 | F32: 162.57 | H32: 179.57 | J32: 179.99 | L32: 179.98 | N32: 176.15 | P32: 179.94 | R32: 179.77 | T32: 179.78 | V32: 175.29 | X32: 179.98 | Z32: 179.97 | AB32: 179.92 | AD32: 179.94 | AF32: 179.74 | AH32: 179.9 | AJ32: 179.91 | AL32: 179.99
A33: UTM EST [m] | B33: 510075.86 | D33: 509861.33 | F33: 509710.43 | H33: 509516.96 | J33: 509278.05 | L33: 509197.73 | N33: 508887.06 | P33: 508599.08 | R33: 508519.71 | T33: 508402.48 | V33: 508230.52 | X33: 508030.67 | Z33: 507894.46 | AB33: 507519.76 | AD33: 507392.85 | AF33: 507208.36 | AH33: 507007.29 | AJ33: 506899.46 | AL33: 506819.99
A34: UTM NORD [m] | B34: 4920544.1 | D34: 4920522.3 | F34: 4920485.8 | H34: 4920498.6 | J34: 4920512.7 | L34: 4920517.4 | N34: 4920535.9 | P34: 4920572.6 | R34: 4920582.8 | T34: 4920597.3 | V34: 4920619.3 | X34: 4920661.8 | Z34: 4920690.8 | AB34: 4920770.5 | AD34: 4920797.3 | AF34: 4920836 | AH34: 4920879.2 | AJ34: 4920902.2 | AL34: 4920919
A35: CAMPATA [m] | C35: 215.63 | E35: 155.27 | G35: 193.9 | I35: 239.32 | K35: 80.46 | M35: 311.22 | O35: 290.3 | Q35: 80.02 | S35: 118.13 | U35: 173.37 | W35: 204.32 | Y35: 139.24 | AA35: 383.08 | AC35: 129.71 | AE35: 188.52 | AG35: 205.66 | AI35: 110.25 | AK35: 81.23
A36: TIRO PER VANO [daN] | C36: =TESATURA_NORMALIZADA!G48 -> 381 | E36: =TESATURA_NORMALIZADA!G49 -> 462 | G36: =TESATURA_NORMALIZADA!G50 -> 332 | I36: =TESATURA_NORMALIZADA!G51 -> 450 | K36: =TESATURA_NORMALIZADA!G52 -> 1013 | M36: =TESATURA_NORMALIZADA!G53 -> 423 | O36: =TESATURA_NORMALIZADA!G54 -> 400 | Q36: =TESATURA_NORMALIZADA!G55 -> 2390 | S36: =TESATURA_NORMALIZADA!G56 -> 429 | U36: =TESATURA_NORMALIZADA!G57 -> 460 | W36: =TESATURA_NORMALIZADA!G58 -> 410 | Y36: =TESATURA_NORMALIZADA!G59 -> 388 | AA36: =TESATURA_NORMALIZADA!G60 -> 409 | AC36: =TESATURA_NORMALIZADA!G61 -> 617 | AE36: =TESATURA_NORMALIZADA!G62 -> 444 | AG36: =TESATURA_NORMALIZADA!G63 -> 467 | AI36: =TESATURA_NORMALIZADA!G64 -> 509 | AK36: DA DEFINIRE
A37: PROGRESSIVA [m] | B37: 0 | D37: 215.63 | F37: 370.9 | H37: 564.8 | J37: 804.12 | L37: 884.58 | N37: 1195.8 | P37: 1486.11 | R37: 1566.13 | T37: 1684.26 | V37: 1857.62 | X37: 2061.94 | Z37: 2201.19 | AB37: 2584.27 | AD37: 2713.98 | AF37: 2902.5 | AH37: 3108.16 | AJ37: 3218.41 | AL37: 3299.63
A38: TIRATA [m] | B38: =SUM(C35:AK35) -> 3299.63
A39: CONDUTTORE E OPGW · PIANO BOBINE
A40: TIPO DI CONDUTTORE | B40: DA DEFINIRE
A41: PIANO BOBINA CONDUTTORE | B41: DA DEFINIRE
A42: TIPO DI OPGW / FIBRA OTTICA | B42: OPGW Prysmian C61 · 48 fibre ottiche · caratteristiche definitive secondo scheda tecnica approvata
A43: PIANO BOBINA OPGW | B43: Bobina nominale 3.500,00 m · lunghezza tirata 3.304,34 m · margine operativo 195,66 m
A44: NOTE DAL PIANO BOBINE | B44: DA DEFINIRE
A46: FERRAMENTA · MONTAGGIO (NUOVO DA INSTALLARE)
A47: CATENA DI AMARRO (DA) | B47: LM252: morsetto 603 + 2×522/2 + 2×401/1 (rif. C23, C51) | D47: LM252: morsetto 603 + 2×522/2 + 2×401/1 (rif. C23, C51) | F47: LM252: morsetto 603 + 2×522/2 + 2×401/1 (rif. C23, C51) | H47: LM252: morsetto 603 + 2×522/2 + 2×401/1 (rif. C23, C51) | J47: LM252: morsetto 603 + 2×522/2 + 2×401/1 (rif. C23, C51) | L47: LM252: morsetto 603 + 2×522/2 + 2×401/1 (rif. C23, C51) | N47: LM252: morsetto 603 + 2×522/2 + 2×401/1 (rif. C23, C51) | P47: LM252: morsetto 603 + 2×522/2 + 2×401/1 (rif. C23, C51) | R47: LM252: morsetto 603 + 2×522/2 + 2×401/1 (rif. C23, C51) | T47: LM252: morsetto 603 + 2×522/2 + 2×401/1 (rif. C23, C51) | V47: LM252: morsetto 603 + 2×522/2 + 2×401/1 (rif. C23, C51) | X47: LM252: morsetto 603 + 2×522/2 + 2×401/1 (rif. C23, C51) | Z47: LM252: morsetto 603 + 2×522/2 + 2×401/1 (rif. C23, C51) | AB47: LM252: morsetto 603 + 2×522/2 + 2×401/1 (rif. C23, C51) | AD47: LM252: morsetto 603 + 2×522/2 + 2×401/1 (rif. C23, C51) | AF47: LM252: morsetto 603 + 2×522/2 + 2×401/1 (rif. C23, C51) | AH47: LM252: morsetto 603 + 2×522/2 + 2×401/1 (rif. C23, C51) | AJ47: LM252: morsetto 603 + 2×522/2 + 2×401/1 (rif. C23, C51) | AL47: LM252: morsetto 603 + 2×522/2 + 2×401/1 (rif. C23, C51)
A48: CATENA DI SOSPENSIONE (V)
A49: CATENA D'ANGOLO (TA2)
A50: CATENA AUSILIARIA
A51: NOTE
A52: FERRAMENTA · SMONTAGGIO (ESISTENTE DA SMONTARE)
A53: CATENA DI AMARRO (DA) | B53: LM252: morsetto 603 + 2×522/2 + 2×401/1 (rif. C23, C51) | D53: LM252: morsetto 603 + 2×522/2 + 2×401/1 (rif. C23, C51) | F53: LM252: morsetto 603 + 2×522/2 + 2×401/1 (rif. C23, C51) | H53: LM252: morsetto 603 + 2×522/2 + 2×401/1 (rif. C23, C51) | J53: LM252: morsetto 603 + 2×522/2 + 2×401/1 (rif. C23, C51) | L53: LM252: morsetto 603 + 2×522/2 + 2×401/1 (rif. C23, C51) | N53: LM252: morsetto 603 + 2×522/2 + 2×401/1 (rif. C23, C51) | P53: LM252: morsetto 603 + 2×522/2 + 2×401/1 (rif. C23, C51) | R53: LM252: morsetto 603 + 2×522/2 + 2×401/1 (rif. C23, C51) | T53: LM252: morsetto 603 + 2×522/2 + 2×401/1 (rif. C23, C51) | V53: LM252: morsetto 603 + 2×522/2 + 2×401/1 (rif. C23, C51) | X53: LM252: morsetto 603 + 2×522/2 + 2×401/1 (rif. C23, C51) | Z53: LM252: morsetto 603 + 2×522/2 + 2×401/1 (rif. C23, C51) | AB53: LM252: morsetto 603 + 2×522/2 + 2×401/1 (rif. C23, C51) | AD53: LM252: morsetto 603 + 2×522/2 + 2×401/1 (rif. C23, C51) | AF53: LM252: morsetto 603 + 2×522/2 + 2×401/1 (rif. C23, C51) | AH53: LM252: morsetto 603 + 2×522/2 + 2×401/1 (rif. C23, C51) | AJ53: LM252: morsetto 603 + 2×522/2 + 2×401/1 (rif. C23, C51) | AL53: LM252: morsetto 603 + 2×522/2 + 2×401/1 (rif. C23, C51)
A54: CATENA DI SOSPENSIONE (V)
A55: CATENA D'ANGOLO (TA2)
A56: CATENA AUSILIARIA
A57: NOTE

Sheet TIRATA_04_285-304
A1: PIANO DI STENDIMENTO · 132 kV QUARTAIE–MOLASSANA · TIRATA 4 · 285–304
D2: PROGETTO 23842B1 · IMPRESA ESECUTRICE ELECNOR | T2: OPGW PRYSMIAN C61 · 48 FIBRE · ETRS89 / UTM 32N
A4: DATI DELLA TIRATA | B4: Lunghezza: 4.044,81 m | L4: Bobina: 4.500,00 m | V4: Margine: 455,19 m | AF4: Tiro: DA DEFINIRE
A5: FRENO · Tesmec PT1250 · sostegno 285 · angolo 35° · distanza 37 m · DIRETTO | V5: ARGANO · Tesmec PL1150 · sostegno 304 · angolo 0° · distanza 13 m · ROVESCIO-RINVIATO
A7: ATTRAVERSAMENTI | B7: 285–286 | D7: 286–287 | F7: 287–288 | H7: 288–289 | J7: 289–290 | L7: 290–291 | N7: 291–292 | P7: 292–293 | R7: 293–294 | T7: 294–295 | V7: 295–296 | X7: 296–297 | Z7: 297–298 | AB7: 298–299 | AD7: 299–300 | AF7: 300–301 | AH7: 301–302 | AJ7: 302–303 | AL7: 303–304 | AN7: FINE
A8: Tipo · riferimento | B8: =IFERROR(INDEX('04 Interferencias'!$D:$D,MATCH(SUBSTITUTE(B7,"–","-"),'04 Interferencias'!$A:$A,0)),"—") -> Pallorcio | D8: =IFERROR(INDEX('04 Interferencias'!$D:$D,MATCH(SUBSTITUTE(D7,"–","-"),'04 Interferencias'!$A:$A,0)),"—") -> 15 kV. | F8: =IFERROR(INDEX('04 Interferencias'!$D:$D,MATCH(SUBSTITUTE(F7,"–","-"),'04 Interferencias'!$A:$A,0)),"—") -> — | H8: =IFERROR(INDEX('04 Interferencias'!$D:$D,MATCH(SUBSTITUTE(H7,"–","-"),'04 Interferencias'!$A:$A,0)),"—") -> — | J8: =IFERROR(INDEX('04 Interferencias'!$D:$D,MATCH(SUBSTITUTE(J7,"–","-"),'04 Interferencias'!$A:$A,0)),"—") -> — | L8: =IFERROR(INDEX('04 Interferencias'!$D:$D,MATCH(SUBSTITUTE(L7,"–","-"),'04 Interferencias'!$A:$A,0)),"—") -> — | N8: =IFERROR(INDEX('04 Interferencias'!$D:$D,MATCH(SUBSTITUTE(N7,"–","-"),'04 Interferencias'!$A:$A,0)),"—") -> — | P8: =IFERROR(INDEX('04 Interferencias'!$D:$D,MATCH(SUBSTITUTE(P7,"–","-"),'04 Interferencias'!$A:$A,0)),"—") -> Rustico Telefonica | R8: =IFERROR(INDEX('04 Interferencias'!$D:$D,MATCH(SUBSTITUTE(R7,"–","-"),'04 Interferencias'!$A:$A,0)),"—") -> 3 MT precordato 2Baracche | T8: =IFERROR(INDEX('04 Interferencias'!$D:$D,MATCH(SUBSTITUTE(T7,"–","-"),'04 Interferencias'!$A:$A,0)),"—") -> Pallorcio e Rustico | V8: =IFERROR(INDEX('04 Interferencias'!$D:$D,MATCH(SUBSTITUTE(V7,"–","-"),'04 Interferencias'!$A:$A,0)),"—") -> SP. Per Cavassolo | X8: =IFERROR(INDEX('04 Interferencias'!$D:$D,MATCH(SUBSTITUTE(X7,"–","-"),'04 Interferencias'!$A:$A,0)),"—") -> — | Z8: =IFERROR(INDEX('04 Interferencias'!$D:$D,MATCH(SUBSTITUTE(Z7,"–","-"),'04 Interferencias'!$A:$A,0)),"—") -> — | AB8: =IFERROR(INDEX('04 Interferencias'!$D:$D,MATCH(SUBSTITUTE(AB7,"–","-"),'04 Interferencias'!$A:$A,0)),"—") -> Sovrapassa Falk | AD8: =IFERROR(INDEX('04 Interferencias'!$D:$D,MATCH(SUBSTITUTE(AD7,"–","-"),'04 Interferencias'!$A:$A,0)),"—") -> BT. | AF8: =IFERROR(INDEX('04 Interferencias'!$D:$D,MATCH(SUBSTITUTE(AF7,"–","-"),'04 Interferencias'!$A:$A,0)),"—") -> Baracca BT. Aerea SC. SV. - Btrame | AH8: =IFERROR(INDEX('04 Interferencias'!$D:$D,MATCH(SUBSTITUTE(AH7,"–","-"),'04 Interferencias'!$A:$A,0)),"—") -> SP. 15 kV precordato. BT in Cavo | AJ8: =IFERROR(INDEX('04 Interferencias'!$D:$D,MATCH(SUBSTITUTE(AJ7,"–","-"),'04 Interferencias'!$A:$A,0)),"—") -> SP. Cavassolo Davagna | AL8: =IFERROR(INDEX('04 Interferencias'!$D:$D,MATCH(SUBSTITUTE(AL7,"–","-"),'04 Interferencias'!$A:$A,0)),"—") -> 2 MT. BT. Casa SP. | AN8: =IFERROR(INDEX('04 Interferencias'!$D:$D,MATCH(SUBSTITUTE(AN7,"–","-"),'04 Interferencias'!$A:$A,0)),"—") -> —
A10: SCHEMA DI STENDIMENTO · RAPPRESENTAZIONE SIMBOLICA NON IN SCALA
A28: N° SOSTEGNO | B28: 285 | D28: 286 | F28: 287 | H28: 288 | J28: 289 | L28: 290 | N28: 291 | P28: 292 | R28: 293 | T28: 294 | V28: 295 | X28: 296 | Z28: 297 | AB28: 298 | AD28: 299 | AF28: 300 | AH28: 301 | AJ28: 302 | AL28: 303 | AN28: 304
A29: TIPO | B29: AMARRO | D29: AMARRO | F29: AMARRO | H29: SOSPENSIONE | J29: SOSPENSIONE | L29: AMARRO | N29: AMARRO | P29: SOSPENSIONE | R29: AMARRO | T29: AMARRO | V29: AMARRO | X29: AMARRO | Z29: SOSPENSIONE | AB29: AMARRO | AD29: SOSPENSIONE | AF29: AMARRO | AH29: AMARRO | AJ29: AMARRO | AL29: AMARRO | AN29: AMARRO
A30: ALTEZZA [m] | B30: 23.5 | D30: 26.9 | F30: 27.2 | H30: 23.4 | J30: 26.9 | L30: 29.2 | N30: 22.3 | P30: 22.3 | R30: 29.1 | T30: 29.1 | V30: 29 | X30: 23.5 | Z30: 26.3 | AB30: 22.3 | AD30: 22.4 | AF30: 24.8 | AH30: 22.3 | AJ30: 21.7 | AL30: 22.3 | AN30: 22.8
A31: QUOTA [m s.l.m.] | B31: 344.01 | D31: 350.27 | F31: 454.85 | H31: 427.41 | J31: 424.77 | L31: 427.29 | N31: 402.44 | P31: 370.52 | R31: 418.31 | T31: 406.43 | V31: 378.76 | X31: 435.35 | Z31: 544.39 | AB31: 517.04 | AD31: 499.63 | AF31: 436.5 | AH31: 407.52 | AJ31: 332.46 | AL31: 307.77 | AN31: 262.1
A32: ANGOLO LINEA [°] | B32: 179.99 | D32: 179.89 | F32: 175.74 | H32: 180 | J32: 179.99 | L32: 167.2 | N32: 179.88 | P32: 179.48 | R32: 167.32 | T32: 178.24 | V32: 179.98 | X32: 179.95 | Z32: 179.9 | AB32: 164.53 | AD32: 179.77 | AF32: 179.87 | AH32: 179.95 | AJ32: 164.11 | AL32: 179.84 | AN32: 179.94
A33: UTM EST [m] | B33: 506819.99 | D33: 506465.05 | F33: 506287.36 | H33: 505959.08 | J33: 505752.8 | L33: 505513.22 | N33: 505434.99 | P33: 505126.31 | R33: 504893.2 | T33: 504723.84 | V33: 504576.53 | X33: 504347.73 | Z33: 504055.65 | AB33: 503919.63 | AD33: 503857.18 | AF33: 503676.08 | AH33: 503477.48 | AJ33: 503215.19 | AL33: 503137.73 | AN33: 503039.72
A34: UTM NORD [m] | B34: 4920919 | D34: 4920994.1 | F34: 4921032.1 | H34: 4921128.2 | J34: 4921188.7 | L34: 4921258.9 | N34: 4921263.7 | P34: 4921282.1 | R34: 4921298.1 | T34: 4921348.6 | V34: 4921397.6 | X34: 4921473.6 | Z34: 4921570.4 | AB34: 4921615.8 | AD34: 4921657.8 | AF34: 4921780.6 | AH34: 4921914.6 | AJ34: 4922091.9 | AL34: 4922117.3 | AN34: 4922149.8
A35: CAMPATA [m] | C35: 362.8 | E35: 181.7 | G35: 342.07 | I35: 214.95 | K35: 249.66 | M35: 78.38 | O35: 309.23 | Q35: 233.66 | S35: 176.73 | U35: 155.22 | W35: 241.11 | Y35: 307.71 | AA35: 143.38 | AC35: 75.25 | AE35: 218.81 | AG35: 239.58 | AI35: 316.6 | AK35: 81.52 | AM35: 103.25
A36: TIRO PER VANO [daN] | C36: DA DEFINIRE | E36: DA DEFINIRE | G36: DA DEFINIRE | I36: DA DEFINIRE | K36: DA DEFINIRE | M36: DA DEFINIRE | O36: DA DEFINIRE | Q36: DA DEFINIRE | S36: DA DEFINIRE | U36: DA DEFINIRE | W36: DA DEFINIRE | Y36: DA DEFINIRE | AA36: DA DEFINIRE | AC36: DA DEFINIRE | AE36: DA DEFINIRE | AG36: DA DEFINIRE | AI36: DA DEFINIRE | AK36: DA DEFINIRE | AM36: DA DEFINIRE
A37: PROGRESSIVA [m] | B37: 0 | D37: 362.8 | F37: 544.5 | H37: 886.58 | J37: 1101.53 | L37: 1351.19 | N37: 1429.57 | P37: 1738.8 | R37: 1972.45 | T37: 2149.19 | V37: 2304.41 | X37: 2545.52 | Z37: 2853.23 | AB37: 2996.61 | AD37: 3071.86 | AF37: 3290.67 | AH37: 3530.25 | AJ37: 3846.85 | AL37: 3928.37 | AN37: 4031.62
A38: TIRATA [m] | B38: =SUM(C35:AM35) -> 4031.61
A39: CONDUTTORE E OPGW · PIANO BOBINE
A40: TIPO DI CONDUTTORE | B40: DA DEFINIRE
A41: PIANO BOBINA CONDUTTORE | B41: DA DEFINIRE
A42: TIPO DI OPGW / FIBRA OTTICA | B42: OPGW Prysmian C61 · 48 fibre ottiche · caratteristiche definitive secondo scheda tecnica approvata
A43: PIANO BOBINA OPGW | B43: Bobina nominale 4.500,00 m · lunghezza tirata 4.044,81 m · margine operativo 455,19 m
A44: NOTE DAL PIANO BOBINE | B44: DA DEFINIRE
A46: FERRAMENTA · MONTAGGIO (NUOVO DA INSTALLARE)
A47: CATENA DI AMARRO (DA) | B47: LM252: morsetto 603 + 2×522/2 + 2×401/1 (rif. C23, C51) | D47: LM252: morsetto 603 + 2×522/2 + 2×401/1 (rif. C23, C51) | F47: LM252: morsetto 603 + 2×522/2 + 2×401/1 (rif. C23, C51) | H47: LM252: morsetto 603 + 2×522/2 + 2×401/1 (rif. C23, C51) | J47: LM252: morsetto 603 + 2×522/2 + 2×401/1 (rif. C23, C51) | L47: LM252: morsetto 603 + 2×522/2 + 2×401/1 (rif. C23, C51) | N47: LM252: morsetto 603 + 2×522/2 + 2×401/1 (rif. C23, C51) | P47: LM252: morsetto 603 + 2×522/2 + 2×401/1 (rif. C23, C51) | R47: LM252: morsetto 603 + 2×522/2 + 2×401/1 (rif. C23, C51) | T47: LM252: morsetto 603 + 2×522/2 + 2×401/1 (rif. C23, C51) | V47: LM252: morsetto 603 + 2×522/2 + 2×401/1 (rif. C23, C51) | X47: LM252: morsetto 603 + 2×522/2 + 2×401/1 (rif. C23, C51) | Z47: LM252: morsetto 603 + 2×522/2 + 2×401/1 (rif. C23, C51) | AB47: LM252: morsetto 603 + 2×522/2 + 2×401/1 (rif. C23, C51) | AD47: LM252: morsetto 603 + 2×522/2 + 2×401/1 (rif. C23, C51) | AF47: LM252: morsetto 603 + 2×522/2 + 2×401/1 (rif. C23, C51) | AH47: LM252: morsetto 603 + 2×522/2 + 2×401/1 (rif. C23, C51) | AJ47: LM252: morsetto 603 + 2×522/2 + 2×401/1 (rif. C23, C51) | AL47: LM252: morsetto 603 + 2×522/2 + 2×401/1 (rif. C23, C51) | AN47: LM252: morsetto 603 + 2×522/2 + 2×401/1 (rif. C23, C51)
A48: CATENA DI SOSPENSIONE (V)
A49: CATENA D'ANGOLO (TA2)
A50: CATENA AUSILIARIA
A51: NOTE
A52: FERRAMENTA · SMONTAGGIO (ESISTENTE DA SMONTARE)
A53: CATENA DI AMARRO (DA) | B53: LM252: morsetto 603 + 2×522/2 + 2×401/1 (rif. C23, C51) | D53: LM252: morsetto 603 + 2×522/2 + 2×401/1 (rif. C23, C51) | F53: LM252: morsetto 603 + 2×522/2 + 2×401/1 (rif. C23, C51) | H53: LM252: morsetto 603 + 2×522/2 + 2×401/1 (rif. C23, C51) | J53: LM252: morsetto 603 + 2×522/2 + 2×401/1 (rif. C23, C51) | L53: LM252: morsetto 603 + 2×522/2 + 2×401/1 (rif. C23, C51) | N53: LM252: morsetto 603 + 2×522/2 + 2×401/1 (rif. C23, C51) | P53: LM252: morsetto 603 + 2×522/2 + 2×401/1 (rif. C23, C51) | R53: LM252: morsetto 603 + 2×522/2 + 2×401/1 (rif. C23, C51) | T53: LM252: morsetto 603 + 2×522/2 + 2×401/1 (rif. C23, C51) | V53: LM252: morsetto 603 + 2×522/2 + 2×401/1 (rif. C23, C51) | X53: LM252: morsetto 603 + 2×522/2 + 2×401/1 (rif. C23, C51) | Z53: LM252: morsetto 603 + 2×522/2 + 2×401/1 (rif. C23, C51) | AB53: LM252: morsetto 603 + 2×522/2 + 2×401/1 (rif. C23, C51) | AD53: LM252: morsetto 603 + 2×522/2 + 2×401/1 (rif. C23, C51) | AF53: LM252: morsetto 603 + 2×522/2 + 2×401/1 (rif. C23, C51) | AH53: LM252: morsetto 603 + 2×522/2 + 2×401/1 (rif. C23, C51) | AJ53: LM252: morsetto 603 + 2×522/2 + 2×401/1 (rif. C23, C51) | AL53: LM252: morsetto 603 + 2×522/2 + 2×401/1 (rif. C23, C51) | AN53: LM252: morsetto 603 + 2×522/2 + 2×401/1 (rif. C23, C51)
A54: CATENA DI SOSPENSIONE (V)
A55: CATENA D'ANGOLO (TA2)
A56: CATENA AUSILIARIA
A57: NOTE

Sheet TIRATA_05_304-317
A1: PIANO DI STENDIMENTO · 132 kV QUARTAIE–MOLASSANA · TIRATA 5 · 304–317
D2: PROGETTO 23842B1 · IMPRESA ESECUTRICE ELECNOR | N2: OPGW PRYSMIAN C61 · 48 FIBRE · ETRS89 / UTM 32N
A4: DATI DELLA TIRATA | B4: Lunghezza: 2.378,12 m | J4: Bobina: 3.200,00 m | R4: Margine: 821,88 m | Z4: Tiro: DA DEFINIRE
A5: FRENO · Tesmec PT1250 · sostegno 304 · angolo 0° · distanza 13 m · DIRETTO | P5: ARGANO · Tesmec PL1150 · sostegno 317 · angolo 0° · distanza 10 m · DIRETTO
A7: ATTRAVERSAMENTI | B7: 304–305 | D7: 305–306 | F7: 306–307 | H7: 307–308 | J7: 308–309 | L7: 309–310 | N7: 310–311 | P7: 311–312 | R7: 312–313 | T7: 313–314 | V7: 314–315 | X7: 315–316 | Z7: 316–317 | AB7: FINE
A8: Tipo · riferimento | B8: =IFERROR(INDEX('04 Interferencias'!$D:$D,MATCH(SUBSTITUTE(B7,"–","-"),'04 Interferencias'!$A:$A,0)),"—") -> SC. BT in cavo | D8: =IFERROR(INDEX('04 Interferencias'!$D:$D,MATCH(SUBSTITUTE(D7,"–","-"),'04 Interferencias'!$A:$A,0)),"—") -> — | F8: =IFERROR(INDEX('04 Interferencias'!$D:$D,MATCH(SUBSTITUTE(F7,"–","-"),'04 Interferencias'!$A:$A,0)),"—") -> — | H8: =IFERROR(INDEX('04 Interferencias'!$D:$D,MATCH(SUBSTITUTE(H7,"–","-"),'04 Interferencias'!$A:$A,0)),"—") -> — | J8: =IFERROR(INDEX('04 Interferencias'!$D:$D,MATCH(SUBSTITUTE(J7,"–","-"),'04 Interferencias'!$A:$A,0)),"—") -> Str. Privata - BT in cavo BT. IP. Fienile Str. Privata | L8: =IFERROR(INDEX('04 Interferencias'!$D:$D,MATCH(SUBSTITUTE(L7,"–","-"),'04 Interferencias'!$A:$A,0)),"—") -> 15 kV precordato. Garage Str.privata | N8: =IFERROR(INDEX('04 Interferencias'!$D:$D,MATCH(SUBSTITUTE(N7,"–","-"),'04 Interferencias'!$A:$A,0)),"—") -> 15kV. SC.BT in cavo 2BT. IP - 2 baracche in lamiera | P8: =IFERROR(INDEX('04 Interferencias'!$D:$D,MATCH(SUBSTITUTE(P7,"–","-"),'04 Interferencias'!$A:$A,0)),"—") -> — | R8: =IFERROR(INDEX('04 Interferencias'!$D:$D,MATCH(SUBSTITUTE(R7,"–","-"),'04 Interferencias'!$A:$A,0)),"—") -> — | T8: =IFERROR(INDEX('04 Interferencias'!$D:$D,MATCH(SUBSTITUTE(T7,"–","-"),'04 Interferencias'!$A:$A,0)),"—") -> — | V8: =IFERROR(INDEX('04 Interferencias'!$D:$D,MATCH(SUBSTITUTE(V7,"–","-"),'04 Interferencias'!$A:$A,0)),"—") -> — | X8: =IFERROR(INDEX('04 Interferencias'!$D:$D,MATCH(SUBSTITUTE(X7,"–","-"),'04 Interferencias'!$A:$A,0)),"—") -> — | Z8: =IFERROR(INDEX('04 Interferencias'!$D:$D,MATCH(SUBSTITUTE(Z7,"–","-"),'04 Interferencias'!$A:$A,0)),"—") -> — | AB8: =IFERROR(INDEX('04 Interferencias'!$D:$D,MATCH(SUBSTITUTE(AB7,"–","-"),'04 Interferencias'!$A:$A,0)),"—") -> —
A10: SCHEMA DI STENDIMENTO · RAPPRESENTAZIONE SIMBOLICA NON IN SCALA
A28: N° SOSTEGNO | B28: 304 | D28: 305 | F28: 306 | H28: 307 | J28: 308 | L28: 309 | N28: 310 | P28: 311 | R28: 312 | T28: 313 | V28: 314 | X28: 315 | Z28: 316 | AB28: 317
A29: TIPO | B29: AMARRO | D29: AMARRO | F29: AMARRO | H29: AMARRO | J29: AMARRO | L29: AMARRO | N29: AMARRO | P29: AMARRO | R29: SOSPENSIONE | T29: AMARRO | V29: SOSPENSIONE | X29: SOSPENSIONE | Z29: AMARRO | AB29: AMARRO
A30: ALTEZZA [m] | B30: 22.8 | D30: 25.1 | F30: 25.2 | H30: 24.3 | J30: 26.9 | L30: 24.4 | N30: 26.4 | P30: 23.2 | R30: 24.3 | T30: 23.4 | V30: 23.7 | X30: 26.8 | Z30: 24.3 | AB30: 32.4
A31: QUOTA [m s.l.m.] | B31: 262.1 | D31: 265 | F31: 296.01 | H31: 342.67 | J31: 358.52 | L31: 306.13 | N31: 273.56 | P31: 284.38 | R31: 378.85 | T31: 410.25 | V31: 389.56 | X31: 298.63 | Z31: 204.12 | AB31: 242.06
A32: ANGOLO LINEA [°] | B32: 179.94 | D32: 179.51 | F32: 168.5 | H32: 178.83 | J32: 155.49 | L32: 179.53 | N32: 179.46 | P32: 179.79 | R32: 179.9 | T32: 145.99 | V32: 179.83 | X32: 179.92 | Z32: 179.94 | AB32: 179.58
A33: UTM EST [m] | B33: 503039.72 | D33: 502711.25 | F33: 502632.66 | H33: 502410.93 | J33: 502345.05 | L33: 502203.62 | N33: 502067.92 | P33: 501874.31 | R33: 501619.54 | T33: 501554.96 | V33: 501503.13 | X33: 501234.62 | Z33: 501098.53 | AB33: 500811.81
A34: UTM NORD [m] | B34: 4922149.8 | D34: 4922258.2 | F34: 4922283.4 | H34: 4922307.8 | J34: 4922316.4 | L34: 4922404.6 | N34: 4922487.8 | P34: 4922608.9 | R34: 4922767 | T34: 4922807.2 | V34: 4922805.3 | X34: 4922796.2 | Z34: 4922791.5 | AB34: 4922781.7
A35: CAMPATA [m] | C35: 345.9 | E35: 82.53 | G35: 223.07 | I35: 66.44 | K35: 166.69 | M35: 159.14 | O35: 228.37 | Q35: 299.83 | S35: 76.08 | U35: 51.86 | W35: 268.66 | Y35: 136.17 | AA35: 286.89
A36: TIRO PER VANO [daN] | C36: DA DEFINIRE | E36: DA DEFINIRE | G36: DA DEFINIRE | I36: DA DEFINIRE | K36: DA DEFINIRE | M36: DA DEFINIRE | O36: DA DEFINIRE | Q36: DA DEFINIRE | S36: DA DEFINIRE | U36: DA DEFINIRE | W36: DA DEFINIRE | Y36: DA DEFINIRE | AA36: DA DEFINIRE
A37: PROGRESSIVA [m] | B37: 0 | D37: 345.9 | F37: 428.43 | H37: 651.5 | J37: 717.94 | L37: 884.63 | N37: 1043.77 | P37: 1272.15 | R37: 1571.97 | T37: 1648.05 | V37: 1699.92 | X37: 1968.58 | Z37: 2104.76 | AB37: 2391.64
A38: TIRATA [m] | B38: =SUM(C35:AA35) -> 2391.63
A39: CONDUTTORE E OPGW · PIANO BOBINE
A40: TIPO DI CONDUTTORE | B40: DA DEFINIRE
A41: PIANO BOBINA CONDUTTORE | B41: DA DEFINIRE
A42: TIPO DI OPGW / FIBRA OTTICA | B42: OPGW Prysmian C61 · 48 fibre ottiche · caratteristiche definitive secondo scheda tecnica approvata
A43: PIANO BOBINA OPGW | B43: Bobina nominale 3.200,00 m · lunghezza tirata 2.378,12 m · margine operativo 821,88 m
A44: NOTE DAL PIANO BOBINE | B44: DA DEFINIRE
A46: FERRAMENTA · MONTAGGIO (NUOVO DA INSTALLARE)
A47: CATENA DI AMARRO (DA) | B47: LM252: morsetto 603 + 2×522/2 + 2×401/1 (rif. C23, C51) | D47: LM252: morsetto 603 + 2×522/2 + 2×401/1 (rif. C23, C51) | F47: LM252: morsetto 603 + 2×522/2 + 2×401/1 (rif. C23, C51) | H47: LM252: morsetto 603 + 2×522/2 + 2×401/1 (rif. C23, C51) | J47: LM252: morsetto 603 + 2×522/2 + 2×401/1 (rif. C23, C51) | L47: LM252: morsetto 603 + 2×522/2 + 2×401/1 (rif. C23, C51) | N47: LM252: morsetto 603 + 2×522/2 + 2×401/1 (rif. C23, C51) | P47: LM252: morsetto 603 + 2×522/2 + 2×401/1 (rif. C23, C51) | R47: LM252: morsetto 603 + 2×522/2 + 2×401/1 (rif. C23, C51) | T47: LM252: morsetto 603 + 2×522/2 + 2×401/1 (rif. C23, C51) | V47: LM252: morsetto 603 + 2×522/2 + 2×401/1 (rif. C23, C51) | X47: LM252: morsetto 603 + 2×522/2 + 2×401/1 (rif. C23, C51) | Z47: LM252: morsetto 603 + 2×522/2 + 2×401/1 (rif. C23, C51) | AB47: LM252: morsetto 603 + 2×522/2 + 2×401/1 (rif. C23, C51)
A48: CATENA DI SOSPENSIONE (V)
A49: CATENA D'ANGOLO (TA2)
A50: CATENA AUSILIARIA
A51: NOTE
A52: FERRAMENTA · SMONTAGGIO (ESISTENTE DA SMONTARE)
A53: CATENA DI AMARRO (DA) | B53: LM252: morsetto 603 + 2×522/2 + 2×401/1 (rif. C23, C51) | D53: LM252: morsetto 603 + 2×522/2 + 2×401/1 (rif. C23, C51) | F53: LM252: morsetto 603 + 2×522/2 + 2×401/1 (rif. C23, C51) | H53: LM252: morsetto 603 + 2×522/2 + 2×401/1 (rif. C23, C51) | J53: LM252: morsetto 603 + 2×522/2 + 2×401/1 (rif. C23, C51) | L53: LM252: morsetto 603 + 2×522/2 + 2×401/1 (rif. C23, C51) | N53: LM252: morsetto 603 + 2×522/2 + 2×401/1 (rif. C23, C51) | P53: LM252: morsetto 603 + 2×522/2 + 2×401/1 (rif. C23, C51) | R53: LM252: morsetto 603 + 2×522/2 + 2×401/1 (rif. C23, C51) | T53: LM252: morsetto 603 + 2×522/2 + 2×401/1 (rif. C23, C51) | V53: LM252: morsetto 603 + 2×522/2 + 2×401/1 (rif. C23, C51) | X53: LM252: morsetto 603 + 2×522/2 + 2×401/1 (rif. C23, C51) | Z53: LM252: morsetto 603 + 2×522/2 + 2×401/1 (rif. C23, C51) | AB53: LM252: morsetto 603 + 2×522/2 + 2×401/1 (rif. C23, C51)
A54: CATENA DI SOSPENSIONE (V)
A55: CATENA D'ANGOLO (TA2)
A56: CATENA AUSILIARIA
A57: NOTE

Sheet TIRATA_06_317-PORTALE MOLASSANA
A1: PIANO DI STENDIMENTO · 132 kV QUARTAIE–MOLASSANA · TIRATA 6 · 317–PORTALE MOLASSANA
D2: PROGETTO 23842B1 · IMPRESA ESECUTRICE ELECNOR | P2: OPGW PRYSMIAN C61 · 48 FIBRE · ETRS89 / UTM 32N
A4: DATI DELLA TIRATA | B4: Lunghezza: 3.078,45 m | J4: Bobina: 3.500,00 m | R4: Margine: 421,55 m | Z4: Tiro: DA DEFINIRE
A5: FRENO · Tesmec PT1250 · sostegno PORTALE MOLASSANA · angolo 0° · distanza 13 m · DIRETTO | R5: ARGANO · Tesmec PL1150 · sostegno 317 · angolo 0° · distanza 10 m · ROVESCIO-RINVIATO
A7: ATTRAVERSAMENTI | B7: 317–318 | D7: 318–319 | F7: 319–320 | H7: 320–321 | J7: 321–322 | L7: 322–323 | N7: 323–324 | P7: 324–325 | R7: 325–326 | T7: 326–327 | V7: 327–328 | X7: 328–329 | Z7: 329–330 | AB7: 330–331 | AD7: 331–PORTALE MOLASSANA | AF7: FINE
A8: Tipo · riferimento | B8: =IFERROR(INDEX('04 Interferencias'!$D:$D,MATCH(SUBSTITUTE(B7,"–","-"),'04 Interferencias'!$A:$A,0)),"—") -> SP. Per Creto | D8: =IFERROR(INDEX('04 Interferencias'!$D:$D,MATCH(SUBSTITUTE(D7,"–","-"),'04 Interferencias'!$A:$A,0)),"—") -> — | F8: =IFERROR(INDEX('04 Interferencias'!$D:$D,MATCH(SUBSTITUTE(F7,"–","-"),'04 Interferencias'!$A:$A,0)),"—") -> 15 kV. 2Pallorci BT. In cavo | H8: =IFERROR(INDEX('04 Interferencias'!$D:$D,MATCH(SUBSTITUTE(H7,"–","-"),'04 Interferencias'!$A:$A,0)),"—") -> Tubo acqua | J8: =IFERROR(INDEX('04 Interferencias'!$D:$D,MATCH(SUBSTITUTE(J7,"–","-"),'04 Interferencias'!$A:$A,0)),"—") -> — | L8: =IFERROR(INDEX('04 Interferencias'!$D:$D,MATCH(SUBSTITUTE(L7,"–","-"),'04 Interferencias'!$A:$A,0)),"—") -> — | N8: =IFERROR(INDEX('04 Interferencias'!$D:$D,MATCH(SUBSTITUTE(N7,"–","-"),'04 Interferencias'!$A:$A,0)),"—") -> 30 kV -15kV | P8: =IFERROR(INDEX('04 Interferencias'!$D:$D,MATCH(SUBSTITUTE(P7,"–","-"),'04 Interferencias'!$A:$A,0)),"—") -> 2- 15 kV. 2Bt in cavo 4- telefoniche - BT. IP. | R8: =IFERROR(INDEX('04 Interferencias'!$D:$D,MATCH(SUBSTITUTE(R7,"–","-"),'04 Interferencias'!$A:$A,0)),"—") -> Garage in lamiera | T8: =IFERROR(INDEX('04 Interferencias'!$D:$D,MATCH(SUBSTITUTE(T7,"–","-"),'04 Interferencias'!$A:$A,0)),"—") -> 4-BT in cavo Via Struppa Cava - Torrente Bisagno SC. Magazz.Com | V8: =IFERROR(INDEX('04 Interferencias'!$D:$D,MATCH(SUBSTITUTE(V7,"–","-"),'04 Interferencias'!$A:$A,0)),"—") -> Str. Privata Baracca Legno | X8: =IFERROR(INDEX('04 Interferencias'!$D:$D,MATCH(SUBSTITUTE(X7,"–","-"),'04 Interferencias'!$A:$A,0)),"—") -> — | Z8: =IFERROR(INDEX('04 Interferencias'!$D:$D,MATCH(SUBSTITUTE(Z7,"–","-"),'04 Interferencias'!$A:$A,0)),"—") -> 15 kV. | AB8: =IFERROR(INDEX('04 Interferencias'!$D:$D,MATCH(SUBSTITUTE(AB7,"–","-"),'04 Interferencias'!$A:$A,0)),"—") -> — | AD8: =IFERROR(INDEX('04 Interferencias'!$D:$D,MATCH(SUBSTITUTE(AD7,"–","-"),'04 Interferencias'!$A:$A,0)),"—") -> — | AF8: =IFERROR(INDEX('04 Interferencias'!$D:$D,MATCH(SUBSTITUTE(AF7,"–","-"),'04 Interferencias'!$A:$A,0)),"—") -> —
A10: SCHEMA DI STENDIMENTO · RAPPRESENTAZIONE SIMBOLICA NON IN SCALA
A28: N° SOSTEGNO | B28: 317 | D28: 318 | F28: 319 | H28: 320 | J28: 321 | L28: 322 | N28: 323 | P28: 324 | R28: 325 | T28: 326 | V28: 327 | X28: 328 | Z28: 329 | AB28: 330 | AD28: 331 | AF28: PORTALE MOLASSANA
A29: TIPO | B29: AMARRO | D29: AMARRO | F29: SOSPENSIONE | H29: AMARRO | J29: AMARRO | L29: AMARRO | N29: SOSPENSIONE | P29: SOSPENSIONE | R29: SOSPENSIONE | T29: AMARRO | V29: AMARRO | X29: AMARRO | Z29: AMARRO | AB29: SOSPENSIONE | AD29: AMARRO | AF29: AMARRO
A30: ALTEZZA [m] | B30: 32.4 | D30: 23.4 | F30: 32.9 | H30: 32.3 | J30: 30.1 | L30: 35.7 | N30: 39.8 | P30: 46.4 | R30: 43.9 | T30: 50.3 | V30: 37 | X30: 40.9 | Z30: 42.8 | AB30: 35.3 | AD30: 31.5 | AF30: 17.6
A31: QUOTA [m s.l.m.] | B31: 242.06 | D31: 305.52 | F31: 338.97 | H31: 402.55 | J31: 450.02 | L31: 463.09 | N31: 369.67 | P31: 350.05 | R31: 179.54 | T31: 122.37 | V31: 149 | X31: 299.97 | Z31: 302.15 | AB31: 233.22 | AD31: 121.46 | AF31: 67.71
A32: ANGOLO LINEA [°] | B32: 179.58 | D32: 179.37 | F32: 179.93 | H32: 179.88 | J32: 158.87 | L32: 119.69 | N32: 178.62 | P32: 179.56 | R32: 177.94 | T32: 167.28 | V32: 145.02 | X32: 156.35 | Z32: 179.98 | AB32: 179.95 | AD32: 136.29
A33: UTM EST [m] | B33: 500811.81 | D33: 500665.86 | F33: 500507.05 | H33: 500304.02 | J33: 500142.28 | L33: 500073.93 | N33: 499878.52 | P33: 499815.46 | R33: 499510.22 | T33: 499406.5 | V33: 499271.51 | X33: 499019.41 | Z33: 498598.24 | AB33: 498367.81 | AD33: 498140.09 | AF33: 498081.73
A34: UTM NORD [m] | B34: 4922781.7 | D34: 4922775.7 | F34: 4922770.8 | H34: 4922764.4 | J34: 4922759 | L34: 4922782.8 | N34: 4922612.2 | P34: 4922554.5 | R34: 4922270.4 | T34: 4922166.7 | V34: 4921953 | X34: 4921847.4 | Z34: 4921854 | AB34: 4921857.8 | AD34: 4921861.3 | AF34: 4921918.8
A35: CAMPATA [m] | C35: 146.07 | E35: 158.88 | G35: 203.13 | I35: 161.83 | K35: 72.38 | M35: 259.35 | O35: 85.52 | Q35: 416.94 | S35: 146.68 | U35: 252.76 | W35: 273.35 | Y35: 421.22 | AA35: 230.46 | AC35: 227.75 | AE35: 81.95
A36: TIRO PER VANO [daN] | C36: DA DEFINIRE | E36: DA DEFINIRE | G36: DA DEFINIRE | I36: DA DEFINIRE | K36: DA DEFINIRE | M36: DA DEFINIRE | O36: DA DEFINIRE | Q36: DA DEFINIRE | S36: DA DEFINIRE | U36: DA DEFINIRE | W36: DA DEFINIRE | Y36: DA DEFINIRE | AA36: DA DEFINIRE | AC36: DA DEFINIRE | AE36: DA DEFINIRE
A37: PROGRESSIVA [m] | B37: 0 | D37: 146.07 | F37: 304.96 | H37: 508.09 | J37: 669.92 | L37: 742.3 | N37: 1001.65 | P37: 1087.17 | R37: 1504.11 | T37: 1650.79 | V37: 1903.55 | X37: 2176.9 | Z37: 2598.12 | AB37: 2828.59 | AD37: 3056.33 | AF37: 3138.28
A38: TIRATA [m] | B38: =SUM(C35:AE35) -> 3138.27
A39: CONDUTTORE E OPGW · PIANO BOBINE
A40: TIPO DI CONDUTTORE | B40: DA DEFINIRE
A41: PIANO BOBINA CONDUTTORE | B41: DA DEFINIRE
A42: TIPO DI OPGW / FIBRA OTTICA | B42: OPGW Prysmian C61 · 48 fibre ottiche · caratteristiche definitive secondo scheda tecnica approvata
A43: PIANO BOBINA OPGW | B43: Bobina nominale 3.500,00 m · lunghezza tirata 3.078,45 m · margine operativo 421,55 m
A44: NOTE DAL PIANO BOBINE | B44: DA DEFINIRE
A46: FERRAMENTA · MONTAGGIO (NUOVO DA INSTALLARE)
A47: CATENA DI AMARRO (DA) | B47: LM252: morsetto 603 + 2×522/2 + 2×401/1 (rif. C23, C51) | D47: LM252: morsetto 603 + 2×522/2 + 2×401/1 (rif. C23, C51) | H47: LM252: morsetto 603 + 2×522/2 + 2×401/1 (rif. C23, C51) | J47: LM252: morsetto 603 + 2×522/2 + 2×401/1 (rif. C23, C51) | L47: LM252: morsetto 603 + 2×522/2 + 2×401/1 (rif. C23, C51) | T47: LM252: morsetto 603 + 2×522/2 + 2×401/1 (rif. C23, C51) | V47: LM252: morsetto 603 + 2×522/2 + 2×401/1 (rif. C23, C51) | X47: LM252: morsetto 603 + 2×522/2 + 2×401/1 (rif. C23, C51) | Z47: LM252: morsetto 603 + 2×522/2 + 2×401/1 (rif. C23, C51) | AD47: LM252: morsetto 603 + 2×522/2 + 2×401/1 (rif. C23, C51) | AF47: LM252: morsetto 603 + 2×522/2 + 2×401/1 (rif. C23, C51)
A48: CATENA DI SOSPENSIONE (V)
A49: CATENA D'ANGOLO (TA2)
A50: CATENA AUSILIARIA
A51: NOTE
A52: FERRAMENTA · SMONTAGGIO (ESISTENTE DA SMONTARE)
A53: CATENA DI AMARRO (DA) | B53: LM252: morsetto 603 + 2×522/2 + 2×401/1 (rif. C23, C51) | D53: LM252: morsetto 603 + 2×522/2 + 2×401/1 (rif. C23, C51) | H53: LM252: morsetto 603 + 2×522/2 + 2×401/1 (rif. C23, C51) | J53: LM252: morsetto 603 + 2×522/2 + 2×401/1 (rif. C23, C51) | L53: LM252: morsetto 603 + 2×522/2 + 2×401/1 (rif. C23, C51) | T53: LM252: morsetto 603 + 2×522/2 + 2×401/1 (rif. C23, C51) | V53: LM252: morsetto 603 + 2×522/2 + 2×401/1 (rif. C23, C51) | X53: LM252: morsetto 603 + 2×522/2 + 2×401/1 (rif. C23, C51) | Z53: LM252: morsetto 603 + 2×522/2 + 2×401/1 (rif. C23, C51) | AD53: LM252: morsetto 603 + 2×522/2 + 2×401/1 (rif. C23, C51) | AF53: LM252: morsetto 603 + 2×522/2 + 2×401/1 (rif. C23, C51)
A54: CATENA DI SOSPENSIONE (V)
A55: CATENA D'ANGOLO (TA2)
A56: CATENA AUSILIARIA
A57: NOTE

Sheet T.842
D1: AOT - Torino | AD1: QUADRO SINOTTICO Linea 132 kV n° 842 QUARTAIE-MOLASSANA
D2: Unità Impianti Genova | Z2: Aggiornamento 26/03/2018
B4: Sostegno | G4: Morsetteria | I4: Isolatori | Q4: Campata | S4: Conduttori | Y4: Corda di guardia | AC4: Attraversamenti
B5: n° | C5: tipo hu (m) | D5: armamento | E5: disposizione fasi | F5: fondazione | G5: conduttore | H5: f.d.g. | I5: tipo | J5: colore | K5: numero | L5: Contrappesi | M5: Antivibranti | N5: Lunghezza | P5: Dislivello | Q5: n° | R5: angolo | S5: tipo | T5: n° | U5: n° terne | V5: Giunti | W5: Fase | X5: Tiro Orizz./ | Y5: tipo | Z5: n° | AA5: n° | AB5: n° | AC5: Comuni
L6: n° x fase | M6: n° x fase/ | N6: progres. | O6: parziale | P6: attacco | R6: deviazione | W6: giunto | X6: (Param) | Z6: funi | AA6: giunti | AB6: sfere | AC6: attraversati
M7: /c.d.g. | R7: °cent S/D
B8: 0 | C8: Portale H15 | D8: DA+3SS | E8: gatto | H8: amarro | I8: Rigida U120 | N8: 0
D9: 4x25kg | K9: 57 | N9: =N11+O9 -> #VALUE! | O9: 186.99 | Q9: 000-102 | S9: Al-Ac Ø 31,5 mm - sez. 585,3 mm² | T9: 1 | U9: 1 | Y9: Alw Ø 11,5 mm | Z9: 1 | AC9: Moconesi (GE) | AD9: SS225
B10: 102 | C10: Poligonale SP | D10: DA+3comp. | E10: doppia terna con T.841 | H10: amarro | I10: U120N | N10: =N8+O9 -> 186.99 | R10: 262c63 | AD10: Capannone Fiume
K11: 216 | N11: =N13+O11 -> #VALUE! | O11: 141.73 | Q11: 102-101 | T11: 1 | U11: 1 | Z11: 0 | AD11: 15kV SC
B12: 101 | C12: N18 | D12: DS | E12: doppia terna con T.841 | H12: amarro | I12: U120N | N12: =N10+O11 -> 328.72 | AD12: Sovrapassa 66kV RFI
K13: 108 | N13: =N15+O13 -> #VALUE! | O13: 73.76 | Q13: 101-224 | T13: 1 | U13: 1 | Y13: Alw Ø 11,5 mm | Z13: 1
B14: 224 | C14: E18 | D14: DA+3SS | E14: doppia terna con T.841 | H14: amarro | I14: U120N | N14: =N12+O13 -> 402.48 | R14: 312c09
B15: ASSEMBLAGGIO | K15: 378 | N15: =N17+O15 -> #VALUE! | O15: 270.71 | Q15: 224-225 | S15: AAAC LIN_C80/11 Ø 14,1 mm - sez. 118,67 mm² | T15: 1 | U15: 2 | Y15: Acciaio rivestito alluminio Ø 9 mm - LIN_C30 | Z15: 1 | AD15: Rustico Torrente SC. Teleferica
B16: =B14+1 -> 225 | C16: L | D16: DA-SA | H16: amarro | I16: U120N | N16: =N14+O15 -> 673.19
K17: 162 | N17: =N19+O17 -> #VALUE! | O17: 188.69 | Q17: 225-226 | T17: 1 | U17: 2 | Z17: 1 | AD17: Torrente Lav
B18: =B16+1 -> 226 | C18: L | D18: SA-DA | H18: amarro | I18: U120N | N18: =N16+O17 -> 861.88
K19: 162 | N19: =N21+O19 -> #VALUE! | O19: 181.28 | Q19: 226-227 | T19: 1 | U19: 2 | Z19: 1 | AD19: SC. BT. IP. Teleferica
